Workbook

Sheet Assumptions
A1: ДОПУЩЕНИЯ BASELINE: Avito Новая мебель
A2: Синий шрифт = входные данные (hardcodes). Жёлтый фон = ключевые параметры.
A4: № | B4: Параметр | C4: Значение | D4: Единица | E4: Источник / обоснование
B5: РЫНОЧНЫЕ ПАРАМЕТРЫ (TOP-DOWN)
A6: 1 | B6: TAM рынка новой мебели РФ | C6: 627 | D6: млрд ₽ | E6: TAdviser 2024; ПМ итоговая п.2.6
A7: 2 | B7: Доля онлайн-сегмента (→ SAM) | C7: 0.3 | D7: % | E7: e-pepper «Онлайн-продажи мебели 2023»
A8: 3 | B8: SAM = TAM × 30% | C8: =C6*C7 -> 188.1 | D8: млрд ₽ | E8: Расчёт: 627 × 0.30
A9: 4 | B9: Доля Avito в SAM (→ SOM) | C9: 0.1 | D9: % | E9: Реалист. 10% SAM (ПМ итог., п.2.6; WB≈15%)
A10: 5 | B10: SOM = SAM × 10% | C10: =C8*C9 -> 18.81 | D10: млрд ₽ | E10: ≈18.8; конс.3%/агресс.15%
A11: 6 | B11: Рост онлайн-рынка YoY | C11: 0.08 | D11: % год | E11: Data Insight: +7–10% в 2023–2024
B13: ПАРАМЕТРЫ СПРОСА (BOTTOM-UP)
A14: 7 | B14: MAU покупателей (старт, янв 2026) | C14: 5000000 | D14: чел. | E14: Данные курса: 5 млн MAU кат. 3.7
A15: 8 | B15: Рост MAU MoM | C15: 0.003 | D15: % мес | E15: Зрелая кат., ~3.7% YoY; BCG: QM→Stars
A16: 9 | B16: CR MAU → контакт | C16: 0.005 | D16: % | E16: Данные курса: CR=0.05 от показов ≈0.5% MAU
A17: 10 | B17: CR контакт → сделка | C17: 0.2 | D17: % | E17: Курс 5–8% от КП; с 2–3 обращ. ≈20%
A18: 11 | B18: Доля отменённых заказов | C18: 0.08 | D18: % | E18: Бенчмарк: 5–12%
B20: МОНЕТИЗАЦИЯ
A21: 12 | B21: Средний чек (AOV) | C21: 45000 | D21: ₽ | E21: Новая мебель 30–80т, медиана 45т; DI 2024
A22: 13 | B22: Рост AOV YoY | C22: 0.05 | D22: % год | E22: Росстат: инфляция ~5–7%
A23: 14 | B23: Доля транз. через платформу (Y1) | C23: 0.18 | D23: % | E23: Данные курса: 18%, рост +2 п.п./год
A24: 15 | B24: Прирост доли транз. / год | C24: 0.02 | D24: п.п./год | E24: Развитие безопасной сделки, доставки
A25: 16 | B25: Take rate (комиссия) | C25: 0.05 | D25: % | E25: Бенчмарк: 3–8%; Ozon~8%, Avito~5%
A26: 17 | B26: Активные продавцы (старт) | C26: 25000 | D26: чел. | E26: ≈600т объявл. ÷ 24 объявл./прод.
A27: 18 | B27: Рост продавцов MoM | C27: 0.005 | D27: % мес | E27: ≈6% YoY; рост мастеров/студий
A28: 19 | B28: ARPU продавца VAS (Y1) | C28: 180 | D28: ₽/мес | E28: Данные курса: 180 ₽/мес
A29: 20 | B29: Рост ARPU YoY | C29: 0.05 | D29: % год | E29: ≈5% YoY — развитие VAS
B31: СЕЗОННОСТЬ (коэфф.)
A32: 21 | B32: Январь | C32: 0.7 | D32: коэфф. | E32: Постновогод. спад
A33: 22 | B33: Февраль | C33: 0.8 | D33: коэфф. | E33: Восстановление
A34: 23 | B34: Март | C34: 0.95 | D34: коэфф. | E34: Весенний ремонт
A35: 24 | B35: Апрель | C35: 1.05 | D35: коэфф. | E35: Сезон ремонтов
A36: 25 | B36: Май | C36: 1 | D36: коэфф. | E36: Праздники
A37: 26 | B37: Июнь | C37: 0.85 | D37: коэфф. | E37: Отпуска
A38: 27 | B38: Июль | C38: 0.75 | D38: коэфф. | E38: Минимум: отпуска
A39: 28 | B39: Август | C39: 0.9 | D39: коэфф. | E39: Восстановление
A40: 29 | B40: Сентябрь | C40: 1.15 | D40: коэфф. | E40: Пик: новоселья
A41: 30 | B41: Октябрь | C41: 1.2 | D41: коэфф. | E41: Пик: ремонты
A42: 31 | B42: Ноябрь | C42: 1.1 | D42: коэфф. | E42: Чёрная пятница
A43: 32 | B43: Декабрь | C43: 0.95 | D43: коэфф. | E43: Предновогод.
B45: ПРОЧИЕ
...

Sheet Baseline Model
A1: BASELINE (Bottom-Up + Top-Down проверка)
C2: 2026 (помесячно)
A3: Метрика | B3: Ед. | C3: Jan | D3: Feb | E3: Mar | F3: Apr | G3: May | H3: Jun | I3: Jul | J3: Aug | K3: Sep | L3: Oct | M3: Nov | N3: Dec | O3: Y1 2026 | P3: Y2 2027 | Q3: Y3 2028 | R3: Y4 2029 | S3: Y5 2030
A5: РЫНОЧНЫЕ ПАРАМЕТРЫ (TOP-DOWN)
A6: SAM онлайн-рынок мебели | B6: млрд ₽ | C6: =Assumptions!C8 -> 188.1 | D6: =Assumptions!C8 -> 188.1 | E6: =Assumptions!C8 -> 188.1 | F6: =Assumptions!C8 -> 188.1 | G6: =Assumptions!C8 -> 188.1 | H6: =Assumptions!C8 -> 188.1 | I6: =Assumptions!C8 -> 188.1 | J6: =Assumptions!C8 -> 188.1 | K6: =Assumptions!C8 -> 188.1 | L6: =Assumptions!C8 -> 188.1 | M6: =Assumptions!C8 -> 188.1 | N6: =Assumptions!C8 -> 188.1 | O6: =Assumptions!C8 -> 188.1 | P6: =O6*(1+Assumptions!C11) -> 203.148 | Q6: =P6*(1+Assumptions!C11) -> 219.39984 | R6: =Q6*(1+Assumptions!C11) -> 236.95183 | S6: =R6*(1+Assumptions!C11) -> 255.90797
A7: SOM (Avito, 10% SAM) | B7: млрд ₽ | C7: =Assumptions!C10 -> 18.81 | D7: =Assumptions!C10 -> 18.81 | E7: =Assumptions!C10 -> 18.81 | F7: =Assumptions!C10 -> 18.81 | G7: =Assumptions!C10 -> 18.81 | H7: =Assumptions!C10 -> 18.81 | I7: =Assumptions!C10 -> 18.81 | J7: =Assumptions!C10 -> 18.81 | K7: =Assumptions!C10 -> 18.81 | L7: =Assumptions!C10 -> 18.81 | M7: =Assumptions!C10 -> 18.81 | N7: =Assumptions!C10 -> 18.81 | O7: =Assumptions!C10 -> 18.81 | P7: =O7*(1+Assumptions!C11) -> 20.3148 | Q7: =P7*(1+Assumptions!C11) -> 21.939984 | R7: =Q7*(1+Assumptions!C11) -> 23.695183 | S7: =R7*(1+Assumptions!C11) -> 25.590797
A9: ВОРОНКА СПРОСА (BOTTOM-UP)
A10: Сезонный коэффициент | B10: коэфф. | C10: =Assumptions!C32 -> 0.7 | D10: =Assumptions!C33 -> 0.8 | E10: =Assumptions!C34 -> 0.95 | F10: =Assumptions!C35 -> 1.05 | G10: =Assumptions!C36 -> 1 | H10: =Assumptions!C37 -> 0.85 | I10: =Assumptions!C38 -> 0.75 | J10: =Assumptions!C39 -> 0.9 | K10: =Assumptions!C40 -> 1.15 | L10: =Assumptions!C41 -> 1.2 | M10: =Assumptions!C42 -> 1.1 | N10: =Assumptions!C43 -> 0.95
A11: MAU покупателей | B11: чел. | C11: =Assumptions!C14 -> 5000000 | D11: =C11*(1+Assumptions!$C$15) -> 5015000 | E11: =D11*(1+Assumptions!$C$15) -> 5030045 | F11: =E11*(1+Assumptions!$C$15) -> 5045135.1 | G11: =F11*(1+Assumptions!$C$15) -> 5060270.5 | H11: =G11*(1+Assumptions!$C$15) -> 5075451.4 | I11: =H11*(1+Assumptions!$C$15) -> 5090677.7 | J11: =I11*(1+Assumptions!$C$15) -> 5105949.7 | K11: =J11*(1+Assumptions!$C$15) -> 5121267.6 | ... N11: =M11*(1+Assumptions!$C$15) -> 5167497.4 | O11: =ROUND(AVERAGE(C11:N11),0) -> 5083331 | P11: =ROUND(O11*(1+Assumptions!$C$15*12),0) -> 5266331 | Q11: =ROUND(P11*(1+Assumptions!$C$15*12),0) -> 5455919 | R11: =ROUND(Q11*(1+Assumptions!$C$15*12),0) -> 5652332 | S11: =ROUND(R11*(1+Assumptions!$C$15*12),0) -> 5855816
A12: CR MAU → контакт | B12: % | C12: =Assumptions!$C$16 -> 0.005 | D12: =Assumptions!$C$16 -> 0.005 | E12: =Assumptions!$C$16 -> 0.005 | F12: =Assumptions!$C$16 -> 0.005 | G12: =Assumptions!$C$16 -> 0.005 | H12: =Assumptions!$C$16 -> 0.005 | I12: =Assumptions!$C$16 -> 0.005 | J12: =Assumptions!$C$16 -> 0.005 | ... N12: =Assumptions!$C$16 -> 0.005
A13: Контакты / мес | B13: шт. | C13: =C11*C12*C10 -> 17500 | D13: =D11*D12*D10 -> 20060 | E13: =E11*E12*E10 -> 23892.714 | F13: =F11*F12*F10 -> 26486.959 | G13: =G11*G12*G10 -> 25301.353 | H13: =H11*H12*H10 -> 21570.668 | I13: =I11*I12*I10 -> 19090.041 | J13: =J11*J12*J10 -> 22976.774 | ... N13: =N11*N12*N10 -> 24545.613 | O13: =SUM(C13:N13) -> 290027.43 | P13: =ROUND(P11*Assumptions!$C$16*Assumptions!$C$47*12,0) -> 300181 | Q13: =ROUND(Q11*Assumptions!$C$16*Assumptions!$C$47*12,0) -> 310987 | R13: =ROUND(R11*Assumptions!$C$16*Assumptions!$C$47*12,0) -> 322183 | S13: =ROUND(S11*Assumptions!$C$16*Assumptions!$C$47*12,0) -> 333782
A14: CR контакт → сделка | B14: % | C14: =Assumptions!$C$17 -> 0.2 | D14: =Assumptions!$C$17 -> 0.2 | E14: =Assumptions!$C$17 -> 0.2 | F14: =Assumptions!$C$17 -> 0.2 | G14: =Assumptions!$C$17 -> 0.2 | H14: =Assumptions!$C$17 -> 0.2 | I14: =Assumptions!$C$17 -> 0.2 | J14: =Assumptions!$C$17 -> 0.2 | ... N14: =Assumptions!$C$17 -> 0.2
A15: Сделки / мес (все) | B15: шт. | C15: =C13*C14 -> 3500 | D15: =D13*D14 -> 4012 | E15: =E13*E14 -> 4778.5427 | F15: =F13*F14 -> 5297.3919 | G15: =G13*G14 -> 5060.2705 | H15: =H13*H14 -> 4314.1336 | I15: =I13*I14 -> 3818.0083 | J15: =J13*J14 -> 4595.3548 | ... N15: =N13*N14 -> 4909.1225 | O15: =SUM(C15:N15) -> 58005.485 | P15: =P13*Assumptions!$C$17 -> 60036.2 | Q15: =Q13*Assumptions!$C$17 -> 62197.4 | R15: =R13*Assumptions!$C$17 -> 64436.6 | S15: =S13*Assumptions!$C$17 -> 66756.4
A16: Доля отменённых | B16: % | C16: =Assumptions!$C$18 -> 0.08 | D16: =Assumptions!$C$18 -> 0.08 | E16: =Assumptions!$C$18 -> 0.08 | F16: =Assumptions!$C$18 -> 0.08 | G16: =Assumptions!$C$18 -> 0.08 | H16: =Assumptions!$C$18 -> 0.08 | I16: =Assumptions!$C$18 -> 0.08 | J16: =Assumptions!$C$18 -> 0.08 | ... N16: =Assumptions!$C$18 -> 0.08
A17: Завершённые сделки / мес | B17: шт. | C17: =C15*(1-C16) -> 3220 | D17: =D15*(1-D16) -> 3691.04 | E17: =E15*(1-E16) -> 4396.2593 | F17: =F15*(1-F16) -> 4873.6005 | G17: =G15*(1-G16) -> 4655.4489 | H17: =H15*(1-H16) -> 3969.003 | I17: =I15*(1-I16) -> 3512.5676 | J17: =J15*(1-J16) -> 4227.7264 | ... N17: =N15*(1-N16) -> 4516.3927 | O17: =SUM(C17:N17) -> 53365.046 | P17: =P15*(1-Assumptions!$C$18) -> 55233.304 | Q17: =Q15*(1-Assumptions!$C$18) -> 57221.608 | R17: =R15*(1-Assumptions!$C$18) -> 59281.672 | S17: =S15*(1-Assumptions!$C$18) -> 61415.888
A19: МОНЕТИЗАЦИЯ
A20: Средний чек (AOV) | B20: ₽ | C20: =Assumptions!$C$21 -> 45000 | D20: =Assumptions!$C$21 -> 45000 | E20: =Assumptions!$C$21 -> 45000 | F20: =Assumptions!$C$21 -> 45000 | G20: =Assumptions!$C$21 -> 45000 | H20: =Assumptions!$C$21 -> 45000 | I20: =Assumptions!$C$21 -> 45000 | J20: =Assumptions!$C$21 -> 45000 | ... O20: =Assumptions!$C$21 -> 45000 | P20: =ROUND(O20*(1+Assumptions!$C$22),0) -> 47250 | Q20: =ROUND(P20*(1+Assumptions!$C$22),0) -> 49613 | R20: =ROUND(Q20*(1+Assumptions!$C$22),0) -> 52094 | S20: =ROUND(R20*(1+Assumptions!$C$22),0) -> 54699
A21: GMV | B21: млн ₽ | C21: =C17*C20/1000000 -> 144.9 | D21: =D17*D20/1000000 -> 166.0968 | E21: =E17*E20/1000000 -> 197.83167 | F21: =F17*F20/1000000 -> 219.31202 | G21: =G17*G20/1000000 -> 209.4952 | H21: =H17*H20/1000000 -> 178.60513 | I21: =I17*I20/1000000 -> 158.06554 | J21: =J17*J20/1000000 -> 190.24769 | ... N21: =N17*N20/1000000 -> 203.23767 | O21: =SUM(C21:N21) -> 2401.4271 | P21: =P17*P20/1000000 -> 2609.7736 | Q21: =Q17*Q20/1000000 -> 2838.9356 | R21: =R17*R20/1000000 -> 3088.2194 | S21: =S17*S20/1000000 -> 3359.3877
A22: Доля транз. через платформу | B22: % | C22: =Assumptions!$C$23 -> 0.18 | D22: =Assumptions!$C$23 -> 0.18 | E22: =Assumptions!$C$23 -> 0.18 | F22: =Assumptions!$C$23 -> 0.18 | G22: =Assumptions!$C$23 -> 0.18 | H22: =Assumptions!$C$23 -> 0.18 | I22: =Assumptions!$C$23 -> 0.18 | J22: =Assumptions!$C$23 -> 0.18 | ... O22: =Assumptions!$C$23 -> 0.18 | P22: =O22+Assumptions!$C$24 -> 0.2 | Q22: =P22+Assumptions!$C$24 -> 0.22 | R22: =Q22+Assumptions!$C$24 -> 0.24 | S22: =R22+Assumptions!$C$24 -> 0.26
A23: Take rate (комиссия) | B23: % | C23: =Assumptions!$C$25 -> 0.05 | D23: =Assumptions!$C$25 -> 0.05 | E23: =Assumptions!$C$25 -> 0.05 | F23: =Assumptions!$C$25 -> 0.05 | G23: =Assumptions!$C$25 -> 0.05 | H23: =Assumptions!$C$25 -> 0.05 | I23: =Assumptions!$C$25 -> 0.05 | J23: =Assumptions!$C$25 -> 0.05 | ... S23: =Assumptions!$C$25 -> 0.05
A24: Доход от комиссий | B24: млн ₽ | C24: =C21*C22*C23 -> 1.3041 | D24: =D21*D22*D23 -> 1.4948712 | E24: =E21*E22*E23 -> 1.780485 | F24: =F21*F22*F23 -> 1.9738082 | G24: =G21*G22*G23 -> 1.8854568 | H24: =H21*H22*H23 -> 1.6074462 | I24: =I21*I22*I23 -> 1.4225899 | J24: =J21*J22*J23 -> 1.7122292 | ... N24: =N21*N22*N23 -> 1.8291391 | O24: =SUM(C24:N24) -> 21.612844 | P24: =P21*P22*P23 -> 26.097736 | Q24: =Q21*Q22*Q23 -> 31.228292 | R24: =R21*R22*R23 -> 37.058633 | S24: =S21*S22*S23 -> 43.67204
A26: ДОХОД ОТ ПРОДАВЦОВ (VAS)
A27: Активные продавцы | B27: чел. | C27: =Assumptions!$C$26 -> 25000 | D27: =ROUND(C27*(1+Assumptions!$C$27),0) -> 25125 | E27: =ROUND(D27*(1+Assumptions!$C$27),0) -> 25251 | F27: =ROUND(E27*(1+Assumptions!$C$27),0) -> 25377 | G27: =ROUND(F27*(1+Assumptions!$C$27),0) -> 25504 | H27: =ROUND(G27*(1+Assumptions!$C$27),0) -> 25632 | I27: =ROUND(H27*(1+Assumptions!$C$27),0) -> 25760 | J27: =ROUND(I27*(1+Assumptions!$C$27),0) -> 25889 | K27: =ROUND(J27*(1+Assumptions!$C$27),0) -> 26018 | ... N27: =ROUND(M27*(1+Assumptions!$C$27),0) -> 26410 | O27: =ROUND(AVERAGE(C27:N27),0) -> 25699 | P27: =ROUND(O27*(1+Assumptions!$C$27*12),0) -> 27241 | Q27: =ROUND(P27*(1+Assumptions!$C$27*12),0) -> 28875 | R27: =ROUND(Q27*(1+Assumptions!$C$27*12),0) -> 30608 | S27: =ROUND(R27*(1+Assumptions!$C$27*12),0) -> 32444
A28: ARPU продавца (VAS) | B28: ₽/мес | C28: =Assumptions!$C$28 -> 180 | D28: =Assumptions!$C$28 -> 180 | E28: =Assumptions!$C$28 -> 180 | F28: =Assumptions!$C$28 -> 180 | G28: =Assumptions!$C$28 -> 180 | H28: =Assumptions!$C$28 -> 180 | I28: =Assumptions!$C$28 -> 180 | J28: =Assumptions!$C$28 -> 180 | ... O28: =Assumptions!$C$28 -> 180 | P28: =ROUND(O28*(1+Assumptions!$C$29),0) -> 189 | Q28: =ROUND(P28*(1+Assumptions!$C$29),0) -> 198 | R28: =ROUND(Q28*(1+Assumptions!$C$29),0) -> 208 | S28: =ROUND(R28*(1+Assumptions!$C$29),0) -> 218
A29: Доход от VAS | B29: млн ₽ | C29: =C27*C28/1000000 -> 4.5 | D29: =D27*D28/1000000 -> 4.5225 | E29: =E27*E28/1000000 -> 4.54518 | F29: =F27*F28/1000000 -> 4.56786 | G29: =G27*G28/1000000 -> 4.59072 | H29: =H27*H28/1000000 -> 4.61376 | I29: =I27*I28/1000000 -> 4.6368 | J29: =J27*J28/1000000 -> 4.66002 | ... N29: =N27*N28/1000000 -> 4.7538 | O29: =SUM(C29:N29) -> 55.51074 | P29: =P27*P28*12/1000000 -> 61.782588 | Q29: =Q27*Q28*12/1000000 -> 68.607 | R29: =R27*R28*12/1000000 -> 76.397568 | S29: =S27*S28*12/1000000 -> 84.873504
A31: ИТОГО BASELINE
A32: ИТОГО ДОХОД | B32: млн ₽ | C32: =C24+C29 -> 5.8041 | D32: =D24+D29 -> 6.0173712 | E32: =E24+E29 -> 6.325665 | F32: =F24+F29 -> 6.5416682 | G32: =G24+G29 -> 6.4761768 | H32: =H24+H29 -> 6.2212062 | I32: =I24+I29 -> 6.0593899 | J32: =J24+J29 -> 6.3722492 | ... S32: =S24+S29 -> 128.54554
A33: GMV (справочно) | B33: млн ₽ | C33: =C21 -> 144.9 | D33: =D21 -> 166.0968 | E33: =E21 -> 197.83167 | F33: =F21 -> 219.31202 | G33: =G21 -> 209.4952 | H33: =H21 -> 178.60513 | I33: =I21 -> 158.06554 | J33: =J21 -> 190.24769 | ... S33: =S21 -> 3359.3877
A34: GMV / SOM (проверка потолка) | B34: % | O34: =O21/O7/1000 -> 0.12766758 | P34: =P21/P7/1000 -> 0.12846662 | Q34: =Q21/Q7/1000 -> 0.12939552 | R34: =R21/R7/1000 -> 0.13033111 | S34: =S21/S7/1000 -> 0.13127327
A35: Рост дохода YoY | B35: % | P35: =(P32-O32)/O32 -> 0.13947407 | Q35: =(Q32-P32)/P32 -> 0.13603691 | R35: =(R32-Q32)/Q32 -> 0.13643381 | S35: =(S32-R32)/R32 -> 0.13299707

Sheet Пояснения
A1: Пояснения к baseline-модели
A3: 1. Краткий бизнес-контекст
A4: Раздел Авито 3.7 «Мебель и мебель на заказ» → подраздел «Новая мебель».
A5: Это двухсторонняя платформа, которая соединяет продавцов разных типов (от мастеров-одиночек и небольших студий до полноценных магазинов и ритейлеров) с покупателями, среди которых выделяются Ready Buyer, Researcher и бюджетный сегмент. В качестве North Star Metric выбрано количество успешных сделок с новой мебелью в месяц — именно этот показатель наиболее точно отражает ценность, которую платформа создаёт для обеих сторон рынка. С точки зрения матрицы BCG, продукт находится в переходной зоне от Question Mark к Stars: рынок онлайн-мебели растёт двузначными темпами, но доля Авито в этом сегменте пока средняя. Стратегически мы делаем ставку на связку «Мастера и студии ↔ Ready Buyer» — именно здесь платформа может предложить уникальный ассортимент и обеспечить быстрый оборот, в отличие от масс-маркет конкурентов вроде Ozon или Wildberries.
A6: Конкуренты Ozon Мебель (покрытие ПВЗ, масс-маркет), Hoff (офлайн+онлайн), Яндекс Маркет (экосистема).
A8: 2. Выбор метода расчёта baseline
A9: При построении baseline-модели я сознательно выбрал bottom-up как основной подход, дополнив его top-down валидацией. Объясню, почему именно такая комбинация. Почему bottom-up в качестве основы? Для продукта на стадии активного роста, когда уже накоплены операционные данные, bottom-up даёт более точную и управляемую модель. У нас есть конкретные цифры: MAU раздела (около 5 млн пользователей), исторические конверсии на каждом этапе воронки, средний чек. Это позволяет выстроить расчёт «снизу вверх» — от активности конкретных пользователей к итоговым бизнес-показателям. Такой подход особенно ценен тем, что каждый параметр модели можно связать с конкретным продуктовым решением: хотим увеличить GMV — понимаем, на какой этап воронки воздействовать. Это делает модель не просто прогнозом, а инструментом для принятия решений. Зачем нужна top-down валидация? Любая bottom-up модель несёт риск «оторваться от реальности» — можно заложить оптимистичные конверсии и получить цифры, которые физически невозможны на данном рынке. Поэтому я использую top-down как «потолок разумности»: TAM (весь рынок мебели России) — 627 млрд ₽ по данным TAdviser SAM (доступный рынок — онлайн-сегмент) — около 188 млрд ₽, то есть примерно 30% от общего рынка SOM (реалистично достижимая доля) — 18,8 млрд ₽ при сценарии 10% от SAM Почему именно 10%? Авито — безусловный лидер в C2C, но в B2C-сегменте мебели картина иная. Wildberries занимает около 15% рынка онлайн-мебели, активно растут Ozon и Hoff. При этом «Новая мебель» — лишь один из подразделов внутри категории. Десять процентов — это взвешенная оценка, которая учитывает и силу бренда Авито, и реальную конкурентную среду.
A11: 3. Цепочка расчёта
A12: 1) MAU × CR(MAU→контакт) × Сезонность → Контакты/мес
A13: 2) Контакты × CR(контакт→сделка) → Сделки/мес
A14: 3) Сделки × (1 − доля отмен) → Завершённые сделки
A15: 4) Завершённые сделки × AOV → GMV
... A42: 7. ПМ Итоговая работа — Яковлев Д.Д. (ЦА, TAM/SAM/SOM, SWOT, BCG, конкуренты)
